Workbook

Sheet Summary
B1: Build cost summary
B3: EUR to NOK rate | C3: 11 | D3: Input. Mid-market rate, Jul 2026 (latest found via web search). Edit to update all EUR lines.
B5: Category | C5: Subcategory | D5: NOK | E5: Share
B6: Water cooling | D6: =SUMIF(Components!$B$2:$B$158,B6,Components!$J$2:$J$158) -> 11757.13 | E6: =IF($D$50=0,0,D6/$D$50) -> 0.58768681
C7: Pump & reservoir | D7: =SUMIFS(Components!$J$2:$J$158,Components!$B$2:$B$158,B6,Components!$C$2:$C$158,C7) -> 1579.52 | E7: =IF($D$50=0,0,D7/$D$50) -> 0.078953202
C8: Radiators | D8: =SUMIFS(Components!$J$2:$J$158,Components!$B$2:$B$158,B6,Components!$C$2:$C$158,C8) -> 1655.65 | E8: =IF($D$50=0,0,D8/$D$50) -> 0.082758603
C9: Blocks | D9: =SUMIFS(Components!$J$2:$J$158,Components!$B$2:$B$158,B6,Components!$C$2:$C$158,C9) -> 2408.76 | E9: =IF($D$50=0,0,D9/$D$50) -> 0.12040323
C10: Valves & quick disconnects | D10: =SUMIFS(Components!$J$2:$J$158,Components!$B$2:$B$158,B6,Components!$C$2:$C$158,C10) -> 1854.47 | E10: =IF($D$50=0,0,D10/$D$50) -> 0.092696734
C11: Fittings | D11: =SUMIFS(Components!$J$2:$J$158,Components!$B$2:$B$158,B6,Components!$C$2:$C$158,C11) -> 2618.62 | E11: =IF($D$50=0,0,D11/$D$50) -> 0.1308932
C12: Tubing | D12: =SUMIFS(Components!$J$2:$J$158,Components!$B$2:$B$158,B6,Components!$C$2:$C$158,C12) -> 481.73 | E12: =IF($D$50=0,0,D12/$D$50) -> 0.024079547
C13: Coolant | D13: =SUMIFS(Components!$J$2:$J$158,Components!$B$2:$B$158,B6,Components!$C$2:$C$158,C13) -> 404.77 | E13: =IF($D$50=0,0,D13/$D$50) -> 0.020232658
C14: Sensors | D14: =SUMIFS(Components!$J$2:$J$158,Components!$B$2:$B$158,B6,Components!$C$2:$C$158,C14) -> 262.45 | E14: =IF($D$50=0,0,D14/$D$50) -> 0.013118712
C15: Filling, testing & tools | D15: =SUMIFS(Components!$J$2:$J$158,Components!$B$2:$B$158,B6,Components!$C$2:$C$158,C15) -> 491.16 | E15: =IF($D$50=0,0,D15/$D$50) -> 0.024550911
B16: CPU delid & thermal | D16: =SUMIF(Components!$B$2:$B$158,B16,Components!$J$2:$J$158) -> 3551.78 | E16: =IF($D$50=0,0,D16/$D$50) -> 0.17753774
C17: Delid tools | D17: =SUMIFS(Components!$J$2:$J$158,Components!$B$2:$B$158,B16,Components!$C$2:$C$158,C17) -> 1006 | E17: =IF($D$50=0,0,D17/$D$50) -> 0.05028548
C18: Direct-die | D18: =SUMIFS(Components!$J$2:$J$158,Components!$B$2:$B$158,B16,Components!$C$2:$C$158,C18) -> 629 | E18: =IF($D$50=0,0,D18/$D$50) -> 0.031440921
C19: Liquid metal | D19: =SUMIFS(Components!$J$2:$J$158,Components!$B$2:$B$158,B16,Components!$C$2:$C$158,C19) -> 218 | E19: =IF($D$50=0,0,D19/$D$50) -> 0.010896854
C20: Paste & putty | D20: =SUMIFS(Components!$J$2:$J$158,Components!$B$2:$B$158,B16,Components!$C$2:$C$158,C20) -> 705.78 | E20: =IF($D$50=0,0,D20/$D$50) -> 0.035278813
C21: Thermal pads | D21: =SUMIFS(Components!$J$2:$J$158,Components!$B$2:$B$158,B16,Components!$C$2:$C$158,C21) -> 598 | E21: =IF($D$50=0,0,D21/$D$50) -> 0.029891369
C22: Protection | D22: =SUMIFS(Components!$J$2:$J$158,Components!$B$2:$B$158,B16,Components!$C$2:$C$158,C22) -> 395 | E22: =IF($D$50=0,0,D22/$D$50) -> 0.019744299
B23: PC build & cabling | D23: =SUMIF(Components!$B$2:$B$158,B23,Components!$J$2:$J$158) -> 1598.35 | E23: =IF($D$50=0,0,D23/$D$50) -> 0.07989443
C24: PSU cable mod | D24: =SUMIFS(Components!$J$2:$J$158,Components!$B$2:$B$158,B23,Components!$C$2:$C$158,C24) -> 1092.45 | E24: =IF($D$50=0,0,D24/$D$50) -> 0.054606732
C25: Internal connectivity | D25: =SUMIFS(Components!$J$2:$J$158,Components!$B$2:$B$158,B23,Components!$C$2:$C$158,C25) -> 452.01 | E25: =IF($D$50=0,0,D25/$D$50) -> 0.022593976
C26: Mounting | D26: =SUMIFS(Components!$J$2:$J$158,Components!$B$2:$B$158,B23,Components!$C$2:$C$158,C26) -> 53.89 | E26: =IF($D$50=0,0,D26/$D$50) -> 0.0026937222
B27: Controller electronics | D27: =SUMIF(Components!$B$2:$B$158,B27,Components!$J$2:$J$158) -> 2649.02 | E27: =IF($D$50=0,0,D27/$D$50) -> 0.13241277
C28: Microcontroller & modules | D28: =SUMIFS(Components!$J$2:$J$158,Components!$B$2:$B$158,B27,Components!$C$2:$C$158,C28) -> 418.57 | E28: =IF($D$50=0,0,D28/$D$50) -> 0.020922459
C29: Semiconductors | D29: =SUMIFS(Components!$J$2:$J$158,Components!$B$2:$B$158,B27,Components!$C$2:$C$158,C29) -> 190.77 | E29: =IF($D$50=0,0,D29/$D$50) -> 0.0095357466
C30: LEDs | D30: =SUMIFS(Components!$J$2:$J$158,Components!$B$2:$B$158,B27,Components!$C$2:$C$158,C30) -> 71.56 | E30: =IF($D$50=0,0,D30/$D$50) -> 0.0035769672
C31: Passives | D31: =SUMIFS(Components!$J$2:$J$158,Components!$B$2:$B$158,B27,Components!$C$2:$C$158,C31) -> 395.28 | E31: =IF($D$50=0,0,D31/$D$50) -> 0.019758295
C32: Fuses & holders | D32: =SUMIFS(Components!$J$2:$J$158,Components!$B$2:$B$158,B27,Components!$C$2:$C$158,C32) -> 189.97 | E32: =IF($D$50=0,0,D32/$D$50) -> 0.0094957581
C33: Connectors & switches | D33: =SUMIFS(Components!$J$2:$J$158,Components!$B$2:$B$158,B27,Components!$C$2:$C$158,C33) -> 564.63 | E33: =IF($D$50=0,0,D33/$D$50) -> 0.028223351
C34: Wire & cable | D34: =SUMIFS(Components!$J$2:$J$158,Components!$B$2:$B$158,B27,Components!$C$2:$C$158,C34) -> 549.45 | E34: =IF($D$50=0,0,D34/$D$50) -> 0.02746457
C35: Insulation | D35: =SUMIFS(Components!$J$2:$J$158,Components!$B$2:$B$158,B27,Components!$C$2:$C$158,C35) -> 107.42 | E35: =IF($D$50=0,0,D35/$D$50) -> 0.0053694496
C36: Prototyping & mounting | D36: =SUMIFS(Components!$J$2:$J$158,Components!$B$2:$B$158,B27,Components!$C$2:$C$158,C36) -> 161.37 | E36: =IF($D$50=0,0,D36/$D$50) -> 0.0080661709
B37: Tools & workshop | D37: =SUMIF(Components!$B$2:$B$158,B37,Components!$J$2:$J$158) -> 460.96 | E37: =IF($D$50=0,0,D37/$D$50) -> 0.023041347
C38: Tools | D38: =SUMIFS(Components!$J$2:$J$158,Components!$B$2:$B$158,B37,Components!$C$2:$C$158,C38) -> 140.23 | E38: =IF($D$50=0,0,D38/$D$50) -> 0.007009476
C39: Consumables | D39: =SUMIFS(Components!$J$2:$J$158,Components!$B$2:$B$158,B37,Components!$C$2:$C$158,C39) -> 139.59 | E39: =IF($D$50=0,0,D39/$D$50) -> 0.0069774853
C40: Workspace | D40: =SUMIFS(Components!$J$2:$J$158,Components!$B$2:$B$158,B37,Components!$C$2:$C$158,C40) -> 181.14 | E40: =IF($D$50=0,0,D40/$D$50) -> 0.0090543855
B41: Shipping, fees & discounts | D41: =SUMIF(Components!$B$2:$B$158,B41,Components!$J$2:$J$158) -> 1543.945 | E41: =IF($D$50=0,0,D41/$D$50) -> 0.077174966
C42: Shipping | D42: =SUMIFS(Components!$J$2:$J$158,Components!$B$2:$B$158,B41,Components!$C$2:$C$158,C42) -> 907.54 | E42: =IF($D$50=0,0,D42/$D$50) -> 0.045363901
...

Sheet Scope
B1: Scope: in-case loop vs external extension
B2: Scope is set per line in Components, column M (blue = editable). Change it there and this sheet updates.
B4: Scope | D4: NOK | E4: Share
B5: In-case loop | D5: =SUMIF(Components!$M$2:$M$158,B5,Components!$J$2:$J$158) -> 11444.103 | E5: =IF($D$7=0,0,D5/$D$7) -> 0.57475748
B6: External extension | D6: =SUMIF(Components!$M$2:$M$158,B6,Components!$J$2:$J$158) -> 8467.0825 | E6: =IF($D$7=0,0,D6/$D$7) -> 0.42524252
B7: Project total | D7: =D5+D6 -> 19911.185 | E7: =IF($D$7=0,0,D7/$D$7) -> 1
B8: Excludes the Not project line (screen protector).
B10: Scope / category | C10: Subcategory | D10: NOK | E10: Share of scope
B11: In-case loop | D11: =D5 -> 11444.103
B12: Water cooling | D12: =SUMIFS(Components!$J$2:$J$158,Components!$M$2:$M$158,"In-case loop",Components!$B$2:$B$158,B12) -> 6769.98 | E12: =IF($D$11=0,0,D12/$D$11) -> 0.59156933
C13: Pump & reservoir | D13: =SUMIFS(Components!$J$2:$J$158,Components!$M$2:$M$158,"In-case loop",Components!$B$2:$B$158,$B$12,Components!$C$2:$C$158,C13) -> 929.52 | E13: =IF($D$11=0,0,D13/$D$11) -> 0.081222621
C14: Radiators | D14: =SUMIFS(Components!$J$2:$J$158,Components!$M$2:$M$158,"In-case loop",Components!$B$2:$B$158,$B$12,Components!$C$2:$C$158,C14) -> 1205.65 | E14: =IF($D$11=0,0,D14/$D$11) -> 0.10535121
C15: Blocks | D15: =SUMIFS(Components!$J$2:$J$158,Components!$M$2:$M$158,"In-case loop",Components!$B$2:$B$158,$B$12,Components!$C$2:$C$158,C15) -> 2408.76 | E15: =IF($D$11=0,0,D15/$D$11) -> 0.21048046
C16: Valves & quick disconnects | D16: =SUMIFS(Components!$J$2:$J$158,Components!$M$2:$M$158,"In-case loop",Components!$B$2:$B$158,$B$12,Components!$C$2:$C$158,C16) -> 100.31 | E16: =IF($D$11=0,0,D16/$D$11) -> 0.0087652133
C17: Fittings | D17: =SUMIFS(Components!$J$2:$J$158,Components!$M$2:$M$158,"In-case loop",Components!$B$2:$B$158,$B$12,Components!$C$2:$C$158,C17) -> 1065.33 | E17: =IF($D$11=0,0,D17/$D$11) -> 0.093089869
C18: Tubing | D18: =SUMIFS(Components!$J$2:$J$158,Components!$M$2:$M$158,"In-case loop",Components!$B$2:$B$158,$B$12,Components!$C$2:$C$158,C18) -> 223.23 | E18: =IF($D$11=0,0,D18/$D$11) -> 0.019506117
C19: Coolant | D19: =SUMIFS(Components!$J$2:$J$158,Components!$M$2:$M$158,"In-case loop",Components!$B$2:$B$158,$B$12,Components!$C$2:$C$158,C19) -> 267.93 | E19: =IF($D$11=0,0,D19/$D$11) -> 0.023412059
C20: Sensors | D20: =SUMIFS(Components!$J$2:$J$158,Components!$M$2:$M$158,"In-case loop",Components!$B$2:$B$158,$B$12,Components!$C$2:$C$158,C20) -> 78.09 | E20: =IF($D$11=0,0,D20/$D$11) -> 0.0068236019
C21: Filling, testing & tools | D21: =SUMIFS(Components!$J$2:$J$158,Components!$M$2:$M$158,"In-case loop",Components!$B$2:$B$158,$B$12,Components!$C$2:$C$158,C21) -> 491.16 | E21: =IF($D$11=0,0,D21/$D$11) -> 0.042918176
B22: CPU delid & thermal | D22: =SUMIFS(Components!$J$2:$J$158,Components!$M$2:$M$158,"In-case loop",Components!$B$2:$B$158,B22) -> 3551.78 | E22: =IF($D$11=0,0,D22/$D$11) -> 0.31035898
C23: Delid tools | D23: =SUMIFS(Components!$J$2:$J$158,Components!$M$2:$M$158,"In-case loop",Components!$B$2:$B$158,$B$22,Components!$C$2:$C$158,C23) -> 1006 | E23: =IF($D$11=0,0,D23/$D$11) -> 0.087905539
C24: Direct-die | D24: =SUMIFS(Components!$J$2:$J$158,Components!$M$2:$M$158,"In-case loop",Components!$B$2:$B$158,$B$22,Components!$C$2:$C$158,C24) -> 629 | E24: =IF($D$11=0,0,D24/$D$11) -> 0.054962807
C25: Liquid metal | D25: =SUMIFS(Components!$J$2:$J$158,Components!$M$2:$M$158,"In-case loop",Components!$B$2:$B$158,$B$22,Components!$C$2:$C$158,C25) -> 218 | E25: =IF($D$11=0,0,D25/$D$11) -> 0.019049113
C26: Paste & putty | D26: =SUMIFS(Components!$J$2:$J$158,Components!$M$2:$M$158,"In-case loop",Components!$B$2:$B$158,$B$22,Components!$C$2:$C$158,C26) -> 705.78 | E26: =IF($D$11=0,0,D26/$D$11) -> 0.06167194
C27: Thermal pads | D27: =SUMIFS(Components!$J$2:$J$158,Components!$M$2:$M$158,"In-case loop",Components!$B$2:$B$158,$B$22,Components!$C$2:$C$158,C27) -> 598 | E27: =IF($D$11=0,0,D27/$D$11) -> 0.052253988
C28: Protection | D28: =SUMIFS(Components!$J$2:$J$158,Components!$M$2:$M$158,"In-case loop",Components!$B$2:$B$158,$B$22,Components!$C$2:$C$158,C28) -> 395 | E28: =IF($D$11=0,0,D28/$D$11) -> 0.034515594
B29: PC build & cabling | D29: =SUMIFS(Components!$J$2:$J$158,Components!$M$2:$M$158,"In-case loop",Components!$B$2:$B$158,B29) -> 1598.35 | E29: =IF($D$11=0,0,D29/$D$11) -> 0.13966582
C30: PSU cable mod | D30: =SUMIFS(Components!$J$2:$J$158,Components!$M$2:$M$158,"In-case loop",Components!$B$2:$B$158,$B$29,Components!$C$2:$C$158,C30) -> 1092.45 | E30: =IF($D$11=0,0,D30/$D$11) -> 0.095459648
C31: Internal connectivity | D31: =SUMIFS(Components!$J$2:$J$158,Components!$M$2:$M$158,"In-case loop",Components!$B$2:$B$158,$B$29,Components!$C$2:$C$158,C31) -> 452.01 | E31: =IF($D$11=0,0,D31/$D$11) -> 0.0394972
C32: Mounting | D32: =SUMIFS(Components!$J$2:$J$158,Components!$M$2:$M$158,"In-case loop",Components!$B$2:$B$158,$B$29,Components!$C$2:$C$158,C32) -> 53.89 | E32: =IF($D$11=0,0,D32/$D$11) -> 0.0047089756
B33: Tools & workshop | D33: =SUMIFS(Components!$J$2:$J$158,Components!$M$2:$M$158,"In-case loop",Components!$B$2:$B$158,B33) -> 460.96 | E33: =IF($D$11=0,0,D33/$D$11) -> 0.040279262
C34: Tools | D34: =SUMIFS(Components!$J$2:$J$158,Components!$M$2:$M$158,"In-case loop",Components!$B$2:$B$158,$B$33,Components!$C$2:$C$158,C34) -> 140.23 | E34: =IF($D$11=0,0,D34/$D$11) -> 0.012253473
C35: Consumables | D35: =SUMIFS(Components!$J$2:$J$158,Components!$M$2:$M$158,"In-case loop",Components!$B$2:$B$158,$B$33,Components!$C$2:$C$158,C35) -> 139.59 | E35: =IF($D$11=0,0,D35/$D$11) -> 0.012197549
C36: Workspace | D36: =SUMIFS(Components!$J$2:$J$158,Components!$M$2:$M$158,"In-case loop",Components!$B$2:$B$158,$B$33,Components!$C$2:$C$158,C36) -> 181.14 | E36: =IF($D$11=0,0,D36/$D$11) -> 0.01582824
B37: Shipping, fees & discounts | D37: =SUMIFS(Components!$J$2:$J$158,Components!$M$2:$M$158,"In-case loop",Components!$B$2:$B$158,B37) -> 713.0325 | E37: =IF($D$11=0,0,D37/$D$11) -> 0.062305672
C38: Shipping | D38: =SUMIFS(Components!$J$2:$J$158,Components!$M$2:$M$158,"In-case loop",Components!$B$2:$B$158,$B$37,Components!$C$2:$C$158,C38) -> 438.83 | E38: =IF($D$11=0,0,D38/$D$11) -> 0.038345515
C39: Import MVA (estimate) | D39: =SUMIFS(Components!$J$2:$J$158,Components!$M$2:$M$158,"In-case loop",Components!$B$2:$B$158,$B$37,Components!$C$2:$C$158,C39) -> 274.2025 | E39: =IF($D$11=0,0,D39/$D$11) -> 0.023960158
B40: Offsets | D40: =SUMIFS(Components!$J$2:$J$158,Components!$M$2:$M$158,"In-case loop",Components!$B$2:$B$158,B40) -> -1650 | E40: =IF($D$11=0,0,D40/$D$11) -> -0.14417907
C41: Sold parts | D41: =SUMIFS(Components!$J$2:$J$158,Components!$M$2:$M$158,"In-case loop",Components!$B$2:$B$158,$B$40,Components!$C$2:$C$158,C41) -> -1650 | E41: =IF($D$11=0,0,D41/$D$11) -> -0.14417907
B43: External extension | D43: =D6 -> 8467.0825
...

Sheet PC parts
B1: PC parts: bought vs listing price
B2: Blue = input (prices from Vlad). Bought and listing prices are per unit. Net bought = qty x bought + offset (credits negative, losses positive).
B4: Part | C4: Spec | D4: Qty | E4: Bought / unit | F4: Offset (+ adds / - credits) | G4: Listing / unit | H4: Net bought | I4: Listing total | J4: Saved | K4: Saved % | L4: Note
B5: Intel Core Ultra 7 270K Plus | C5: CPU | D5: 1 | E5: 2999 | F5: -2100 | G5: 3600 | H5: =D5*E5+F5 -> 899 | I5: =D5*G5 -> 3600 | J5: =I5-H5 -> 2701 | K5: =IF(I5=0,0,J5/I5) -> 0.75027778 | L5: Offset 2 100 kr from selling the 285K (itself offset by the RAM sale)
B6: ASUS ROG Maximus Z890 Apex | C6: Motherboard | D6: 1 | E6: 2500 | F6: 0 | G6: 5500 | H6: =D6*E6+F6 -> 2500 | I6: =D6*G6 -> 5500 | J6: =I6-H6 -> 3000 | K6: =IF(I6=0,0,J6/I6) -> 0.54545455
B7: G.Skill TZ5CK | C7: DDR5 8400 CUDIMM | D7: 1 | E7: 6783 | F7: 0 | G7: 16800 | H7: =D7*E7+F7 -> 6783 | I7: =D7*G7 -> 16800 | J7: =I7-H7 -> 10017 | K7: =IF(I7=0,0,J7/I7) -> 0.59625 | L7: Listing = current price
B8: HyperX Fury SSD | C8: PCIe 4.0 | D8: 1 | E8: 2490 | F8: 0 | G8: 4400 | H8: =D8*E8+F8 -> 2490 | I8: =D8*G8 -> 4400 | J8: =I8-H8 -> 1910 | K8: =IF(I8=0,0,J8/I8) -> 0.43409091
B9: Corsair RM1000e | C9: PSU | D9: 1 | E9: 1000 | F9: -1000 | G9: 1900 | H9: =D9*E9+F9 -> 0 | I9: =D9*G9 -> 1900 | J9: =I9-H9 -> 1900 | K9: =IF(I9=0,0,J9/I9) -> 1 | L9: Offset 1 000 kr from the same RAM sale as the 270K offset
B10: Noctua NF-A12x25 G2 | C10: 120 mm fan | D10: 4 | E10: 340 | F10: 0 | G10: 340 | H10: =D10*E10+F10 -> 1360 | I10: =D10*G10 -> 1360 | J10: =I10-H10 -> 0 | K10: =IF(I10=0,0,J10/I10) -> 0
B11: Noctua NF-A12x25 G1 | C11: 120 mm fan | D11: 3 | E11: 220 | F11: 0 | G11: 300 | H11: =D11*E11+F11 -> 660 | I11: =D11*G11 -> 900 | J11: =I11-H11 -> 240 | K11: =IF(I11=0,0,J11/I11) -> 0.26666667
B12: ASUS TUF RTX 4070 Ti Super | C12: GPU | D12: 1 | E12: 5700 | F12: 1200 | G12: 9000 | H12: =D12*E12+F12 -> 6900 | I12: =D12*G12 -> 9000 | J12: =I12-H12 -> 2100 | K12: =IF(I12=0,0,J12/I12) -> 0.23333333 | L12: Loss on the old 4070 Ti: bought 6 200, sold 5 000
B13: Total | F13: =SUM(F5:F12) -> -1900 | H13: =SUM(H5:H12) -> 21592 | I13: =SUM(I5:I12) -> 43460 | J13: =SUM(J5:J12) -> 21868 | K13: =IF(I13=0,0,J13/I13) -> 0.50317533
B16: Whole build
B17: Cooling & mod project (Scope sheet) | H17: =Scope!D7 -> 19911.185
B18: PC parts (net bought) | H18: =H13 -> 21592
B19: Total | H19: =H17+H18 -> 41503.185
B21: Total value of all parts
B22: Cooling & mod parts (at cost, excl. sold-parts offset) | H22: =Scope!D7-SUMIF(Components!$B$2:$B$158,"Offsets",Components!$J$2:$J$158) -> 21561.185
B23: PC parts (listing value) | H23: =I13 -> 43460
B24: Total value of all parts | H24: =H22+H23 -> 65021.185
B25: Cooling parts have no listing price, so they are valued at what was paid (incl. shipping and import MVA). The 1 650 kr rebate is excluded since it is not a part.

Sheet Trade history
B1: Trade history: hardware bought, sold and kept
B2: Blue = amounts from Vlad. Yellow = assumption to confirm. Green = current value linked from the PC parts sheet.
B4: Purchases
B5: Deal | C5: What was bought | D5: Price paid
B6: 1 | C6: Bundle: 285K, Z890 TUF, 64 GB Kingston Server Premier 4800, RM1000e, be quiet! 802, Cooler Master 360 AIO, Samsung 500 GB SSD | D6: 10500
B7: 2 | C7: G.Skill TZ5RK (AliExpress) | D7: 7600
B8: 3 | C8: ASUS ROG Maximus Z890 Apex | D8: 2500
B9: 4 | C9: ASUS ROG Strix Z890-F | D9: 500
B10: 5 | C10: Lightloop 360 AIO | D10: 1550
B11: 6 | C11: HyperX Fury 2 TB PCIe 4.0 SSD | D11: 2490
B12: 7 | C12: RTX 4070 Ti | D12: 6200
B13: 8 | C13: Bundle: ASUS TUF 4070 Ti Super (5 700) + Corsair RM850e (500) | D13: 6200
B14: 9 | C14: Bundle: 265KF, Z890 Eagle WiFi 7, 48 GB TZ5CK, Peerless Assassin 140 | D14: 11300
B15: 10 | C15: Contact frame | D15: 60
C16: Total bought | D16: =SUM(D6:D15) -> 48900
B18: Items & outcome
B19: Deal | C19: Item | D19: Outcome | E19: Sold for | F19: Current value (kept) | G19: Note
B20: 1 | C20: Intel Core Ultra 9 285K | D20: Sold | E20: 3500
B21: 1 | C21: ASUS TUF Z890 | D21: Sold | E21: 1200
B22: 1 | C22: Kingston Server Premier 64 GB 4800 | D22: Sold | E22: 7900
B23: 1 | C23: Corsair RM1000e | D23: Kept, this rig | F23: ='PC parts'!G9 -> 1900
B24: 1 | C24: be quiet! 802 | D24: Kept, other rig | G24: Not valued
B25: 1 | C25: Cooler Master 360 AIO | D25: Kept, other rig | G25: Not valued
B26: 1 | C26: Samsung 500 GB SSD | D26: Sold in bundle | G26: See bundle sale line
B27: 2 | C27: G.Skill TZ5RK | D27: Sold in bundle | G27: See bundle sale line
B28: 3 | C28: ASUS ROG Maximus Z890 Apex | D28: Kept, this rig | F28: ='PC parts'!G6 -> 5500
B29: 4 | C29: ASUS ROG Strix Z890-F | D29: Sold in bundle | G29: See bundle sale line
B30: 5 | C30: Lightloop 360 AIO | D30: Sold in bundle | G30: Its 1 500 kr share of the bundle sale is used as part of the 1 650 kr Scope rebate
B31: 6 | C31: HyperX Fury 2 TB SSD | D31: Kept, this rig | F31: ='PC parts'!G8 -> 4400
B32: 7 | C32: RTX 4070 Ti | D32: Sold | E32: 5000 | G32: Confirmed
B33: 8 | C33: ASUS TUF RTX 4070 Ti Super | D33: Kept, this rig | F33: ='PC parts'!G12 -> 9000
B34: 8 | C34: Corsair RM850e | D34: Kept, spare | G34: Kept as a spare for now; not valued
B35: 9 | C35: Intel Core Ultra 7 265KF | D35: Sold in bundle | G35: See bundle sale line
B36: 9 | C36: Gigabyte Z890 Eagle WiFi 7 | D36: Sold | E36: 1350
B37: 9 | C37: G.Skill TZ5CK 48 GB | D37: Kept, this rig | F37: ='PC parts'!G7 -> 16800
B38: 9 | C38: Thermalright Peerless Assassin 140 | D38: Sold | E38: 350
B39: 10 | C39: Contact frame | D39: Sold | E39: 150 | G39: Sold separately; part of the 1 650 kr Scope rebate
B40: - | C40: Bundle sale: 265KF + TZ5RK + Strix Z890-F + Lightloop 360 + Samsung 500 GB | D40: Sold (bundle) | E40: 12490
C41: Total | E41: =SUM(E20:E40) -> 31940 | F41: =SUM(F20:F40) -> 37600
B43: Result
...

Sheet Components
A1: # | B1: Category | C1: Subcategory | D1: Part | E1: Spec / variant | F1: Qty | G1: Shop | H1: Price paid | I1: Currency | J1: Price NOK (incl. MVA) | K1: Status | L1: Note | M1: Scope
A2: 1 | B2: Water cooling | C2: Pump & reservoir | D2: Bykski B-UL-D5-X-V4 D5 pump + reservoir | E2: 100 mm reservoir | F2: 1 | G2: AliExpress | H2: 929.52 | I2: NOK | J2: =IF(I2="EUR",H2*Summary!$C$3,H2) -> 929.52 | K2: Awaiting delivery | M2: In-case loop
A3: 2 | B3: Water cooling | C3: Pump & reservoir | D3: EKWB D5 pump + reservoir | E3: Used | F3: 1 | G3: Finn.no (used) | H3: 650 | I3: NOK | J3: =IF(I3="EUR",H3*Summary!$C$3,H3) -> 650 | K3: Bought (used) | L3: 1 300 kr Finn bundle, split by estimated used value | M3: External extension
A4: 3 | B4: Water cooling | C4: Radiators | D4: Bykski 360 mm radiator D40 V2 | E4: Full copper | F4: 1 | G4: Bykski (Order #EU4231) | H4: 1005.65 | I4: NOK | J4: =IF(I4="EUR",H4*Summary!$C$3,H4) -> 1005.65 | K4: Ordered | L4: Ex-MVA price + 25% MVA | M4: In-case loop
A5: 4 | B5: Water cooling | C5: Radiators | D5: EK XE 240 radiator | E5: 60 mm, used (outdoor) | F5: 1 | G5: Finn.no (used) | H5: 450 | I5: NOK | J5: =IF(I5="EUR",H5*Summary!$C$3,H5) -> 450 | K5: Bought (used) | L5: 1 300 kr Finn bundle, split by estimated used value | M5: External extension
A6: 5 | B6: Water cooling | C6: Radiators | D6: 120 mm radiator | E6: 30 mm, used (rear) | F6: 1 | G6: Finn.no (used) | H6: 200 | I6: NOK | J6: =IF(I6="EUR",H6*Summary!$C$3,H6) -> 200 | K6: Bought (used) | L6: 1 300 kr Finn bundle, split by estimated used value | M6: In-case loop
A7: 6 | B7: Water cooling | C7: Blocks | D7: GPU water block ASUS TUF 4070 Ti | E7: Incl. backplate | F7: 1 | G7: Bykski (Order #EU4231) | H7: 1676.19 | I7: NOK | J7: =IF(I7="EUR",H7*Summary!$C$3,H7) -> 1676.19 | K7: Ordered | L7: Ex-MVA price + 25% MVA (rounded to match order total) | M7: In-case loop
A8: 7 | B8: Water cooling | C8: Blocks | D8: IceManCooler dual-channel memory water block | E8: Black | F8: 1 | G8: AliExpress | H8: 506.25 | I8: NOK | J8: =IF(I8="EUR",H8*Summary!$C$3,H8) -> 506.25 | K8: Awaiting delivery | M8: In-case loop
A9: 8 | B9: Water cooling | C9: Blocks | D9: Bykski DDR5 RAM heatsink (water cooling) | E9: 2 pcs | F9: 1 | G9: AliExpress | H9: 226.32 | I9: NOK | J9: =IF(I9="EUR",H9*Summary!$C$3,H9) -> 226.32 | K9: Awaiting delivery | M9: In-case loop
A10: 9 | B10: Water cooling | C10: Valves & quick disconnects | D10: Motorized ball valve CR02 | E10: 3-way, 12 V DC, DN15 | F10: 1 | G10: AliExpress | H10: 586.92 | I10: NOK | J10: =IF(I10="EUR",H10*Summary!$C$3,H10) -> 586.92 | K10: Processing | M10: External extension
A11: 10 | B11: Water cooling | C11: Valves & quick disconnects | D11: AICANTEC solenoid valve | E11: 12 V DC, 1/2" | F11: 1 | G11: AliExpress | H11: 303.19 | I11: NOK | J11: =IF(I11="EUR",H11*Summary!$C$3,H11) -> 303.19 | K11: Awaiting delivery | M11: External extension
A12: 11 | B12: Water cooling | C12: Valves & quick disconnects | D12: AICANTEC solenoid valve | E12: 12 V DC, 1/4" | F12: 1 | G12: AliExpress | H12: 18.11 | I12: EUR | J12: =IF(I12="EUR",H12*Summary!$C$3,H12) -> 199.21 | K12: Awaiting delivery | M12: External extension
A13: 12 | B13: Water cooling | C13: Valves & quick disconnects | D13: Bykski hand-tighten drain valve G1/4 | E13: Black | F13: 1 | G13: AliExpress | H13: 100.31 | I13: NOK | J13: =IF(I13="EUR",H13*Summary!$C$3,H13) -> 100.31 | K13: Processing | M13: In-case loop
A14: 13 | B14: Water cooling | C14: Valves & quick disconnects | D14: Alphacool Eiszapfen quick-release coupling G1/4 AG | E14: Deep Black | F14: 2 | G14: Alphacool | H14: 31.9 | I14: EUR | J14: =IF(I14="EUR",H14*Summary!$C$3,H14) -> 350.9 | K14: Ordered | M14: External extension
A15: 14 | B15: Water cooling | C15: Valves & quick disconnects | D15: Alphacool Eiszapfen quick-release connector G1/4 IG | E15: Deep Black | F15: 2 | G15: Alphacool | H15: 28.54 | I15: EUR | J15: =IF(I15="EUR",H15*Summary!$C$3,H15) -> 313.94 | K15: Ordered | M15: External extension
A16: 15 | B16: Water cooling | C16: Fittings | D16: Barrow THKN-3/8-B03 compression fitting | E16: 10/13 mm, black | F16: 2 | G16: AliExpress | H16: 89.33 | I16: NOK | J16: =IF(I16="EUR",H16*Summary!$C$3,H16) -> 89.33 | K16: Processing | M16: External extension
A17: 16 | B17: Water cooling | C17: Fittings | D17: Barrow soft-tube compression fittings | E17: ID10/OD13, black, 12-pack | F17: 1 | G17: AliExpress | H17: 278.79 | I17: NOK | J17: =IF(I17="EUR",H17*Summary!$C$3,H17) -> 278.79 | K17: Awaiting delivery | M17: External extension
A18: 17 | B18: Water cooling | C18: Fittings | D18: 10x13 Flex Fitting V2 | E18: Black | F18: 16 | G18: Bykski (Order #EU4231) | H18: 803.6 | I18: NOK | J18: =IF(I18="EUR",H18*Summary!$C$3,H18) -> 803.6 | K18: Ordered | L18: Ex-MVA price + 25% MVA | M18: In-case loop
A19: 18 | B19: Water cooling | C19: Fittings | D19: Alphacool HF 13/10 screw-on barb G1/4 | E19: Deep Black | F19: 8 | G19: Alphacool | H19: 25.44 | I19: EUR | J19: =IF(I19="EUR",H19*Summary!$C$3,H19) -> 279.84 | K19: Ordered | M19: External extension
A20: 19 | B20: Water cooling | C20: Fittings | D20: Bykski 3-way cubic splitter G1/4 | E20: Black | F20: 2 | G20: AliExpress | H20: 172.26 | I20: NOK | J20: =IF(I20="EUR",H20*Summary!$C$3,H20) -> 172.26 | K20: Processing | M20: External extension
A21: 20 | B21: Water cooling | C21: Fittings | D21: Freezemod Y-splitter | E21: Black | F21: 1 | G21: AliExpress | H21: 34.98 | I21: NOK | J21: =IF(I21="EUR",H21*Summary!$C$3,H21) -> 34.98 | K21: Processing | M21: External extension
A22: 21 | B22: Water cooling | C22: Fittings | D22: Cube adapter 3-way | E22: Black | F22: 1 | G22: Bykski (Order #EU4231) | H22: 61.4 | I22: NOK | J22: =IF(I22="EUR",H22*Summary!$C$3,H22) -> 61.4 | K22: Ordered | L22: Ex-MVA price + 25% MVA | M22: In-case loop
A23: 22 | B23: Water cooling | C23: Fittings | D23: Alphacool HF 5-way distributor G1/4 IG | E23: Deep Black | F23: 1 | G23: Alphacool | H23: 5.36 | I23: EUR | J23: =IF(I23="EUR",H23*Summary!$C$3,H23) -> 58.96 | K23: Ordered | M23: External extension
A24: 23 | B24: Water cooling | C24: Fittings | D24: Alphacool Eiszapfen L-connector rotatable G1/4 | E24: Deep Black, 4-pack | F24: 1 | G24: Alphacool | H24: 19.31 | I24: EUR | J24: =IF(I24="EUR",H24*Summary!$C$3,H24) -> 212.41 | K24: Ordered | M24: External extension
A25: 24 | B25: Water cooling | C25: Fittings | D25: Bykski extension fitting F-M | E25: Black, 7.5 mm | F25: 2 | G25: AliExpress | H25: 82.76 | I25: NOK | J25: =IF(I25="EUR",H25*Summary!$C$3,H25) -> 82.76 | K25: Processing | M25: External extension
A26: 25 | B26: Water cooling | C26: Fittings | D26: Extension M/F | E26: Black, 7.5 mm | F26: 1 | G26: Bykski (Order #EU4231) | H26: 33.39 | I26: NOK | J26: =IF(I26="EUR",H26*Summary!$C$3,H26) -> 33.39 | K26: Ordered | L26: Ex-MVA price + 25% MVA | M26: In-case loop
A27: 26 | B27: Water cooling | C27: Fittings | D27: Bykski B-DTJ-MI mini double male | E27: Black | F27: 2 | G27: AliExpress | H27: 67.97 | I27: NOK | J27: =IF(I27="EUR",H27*Summary!$C$3,H27) -> 67.97 | K27: Processing | M27: External extension
A28: 27 | B28: Water cooling | C28: Fittings | D28: Brass hex bushing | E28: F1/4 to M1/2 | F28: 2 | G28: AliExpress | H28: 63.58 | I28: NOK | J28: =IF(I28="EUR",H28*Summary!$C$3,H28) -> 63.58 | K28: Awaiting delivery | M28: External extension
A29: 28 | B29: Water cooling | C29: Fittings | D29: G1/4 knurled stop plug | E29: White | F29: 5 | G29: Bykski (Order #EU4231) | H29: 166.94 | I29: NOK | J29: =IF(I29="EUR",H29*Summary!$C$3,H29) -> 166.94 | K29: Ordered | L29: Ex-MVA price + 25% MVA | M29: In-case loop
A30: 29 | B30: Water cooling | C30: Fittings | D30: Alphacool HF slot panel "Panama" | E30: PCI slot pass-through | F30: 1 | G30: Alphacool | H30: 19.31 | I30: EUR | J30: =IF(I30="EUR",H30*Summary!$C$3,H30) -> 212.41 | K30: Ordered | M30: External extension
A31: 30 | B31: Water cooling | C31: Tubing | D31: Bykski 10x13 PVC tube | E31: Clear, 3 m | F31: 2 | G31: Bykski (Order #EU4231) | H31: 223.23 | I31: NOK | J31: =IF(I31="EUR",H31*Summary!$C$3,H31) -> 223.23 | K31: Ordered | L31: Ex-MVA price + 25% MVA | M31: In-case loop
A32: 31 | B32: Water cooling | C32: Tubing | D32: Alphacool EPDM tube 13/10 | E32: Black, 3.3 m | F32: 2 | G32: Alphacool | H32: 23.5 | I32: EUR | J32: =IF(I32="EUR",H32*Summary!$C$3,H32) -> 258.5 | K32: Ordered | M32: External extension
A33: 32 | B33: Water cooling | C33: Coolant | D33: Double Protect Ultra 1 L | E33: Clear | F33: 2 | G33: Bykski (Order #EU4231) | H33: 267.93 | I33: NOK | J33: =IF(I33="EUR",H33*Summary!$C$3,H33) -> 267.93 | K33: Ordered | L33: Ex-MVA price + 25% MVA | M33: In-case loop
A34: 33 | B34: Water cooling | C34: Coolant | D34: Ethylene glycol pure 500 ml (WARCHEM) | F34: 2 | G34: Order #81860 | H34: 12.44 | I34: EUR | J34: =IF(I34="EUR",H34*Summary!$C$3,H34) -> 136.84 | K34: Ordered | L34: No MVA charged | M34: External extension
A35: 34 | B35: Water cooling | C35: Sensors | D35: Bykski B-PD5-TMR temperature probe | E35: Silver | F35: 3 | G35: AliExpress | H35: 16.76 | I35: EUR | J35: =IF(I35="EUR",H35*Summary!$C$3,H35) -> 184.36 | K35: Awaiting delivery | M35: External extension
A36: 35 | B36: Water cooling | C36: Sensors | D36: Bykski temperature sensor plug G1/4 | E36: Black | F36: 1 | G36: Bykski (Order #EU4231) | H36: 78.09 | I36: NOK | J36: =IF(I36="EUR",H36*Summary!$C$3,H36) -> 78.09 | K36: Ordered | L36: Ex-MVA price + 25% MVA | M36: In-case loop
A37: 36 | B37: Water cooling | C37: Filling, testing & tools | D37: Bykski Leak Tester V5 (B-DTH-K40-V5) | F37: 1 | G37: Bykski (Order #EU4231) | H37: 335.12 | I37: NOK | J37: =IF(I37="EUR",H37*Summary!$C$3,H37) -> 335.12 | K37: Ordered | L37: Ex-MVA price + 25% MVA | M37: In-case loop
A38: 37 | B38: Water cooling | C38: Filling, testing & tools | D38: Fill bottle 250 ml | F38: 1 | G38: Bykski (Order #EU4231) | H38: 55.74 | I38: NOK | J38: =IF(I38="EUR",H38*Summary!$C$3,H38) -> 55.74 | K38: Ordered | L38: Ex-MVA price + 25% MVA | M38: In-case loop
A39: 38 | B39: Water cooling | C39: Filling, testing & tools | D39: 24-pin ATX bridging plug | F39: 1 | G39: Bykski (Order #EU4231) | H39: 33.39 | I39: NOK | J39: =IF(I39="EUR",H39*Summary!$C$3,H39) -> 33.39 | K39: Ordered | L39: Ex-MVA price + 25% MVA | M39: In-case loop
A40: 39 | B40: Water cooling | C40: Filling, testing & tools | D40: Hose cutter | F40: 1 | G40: Bykski (Order #EU4231) | H40: 66.91 | I40: NOK | J40: =IF(I40="EUR",H40*Summary!$C$3,H40) -> 66.91 | K40: Ordered | L40: Ex-MVA price + 25% MVA | M40: In-case loop
...

Sheet Rev 4b BOM
A1: # | B1: Board | C1: Refs | D1: Part | E1: Value / spec | F1: Qty needed | G1: Components # | H1: Status (from Components) | I1: Note
A2: 1 | B2: Board 1 | C2: F1–F3 | D2: 5x20 PCB fuse clip holder | E2: 25.5x9 mm, clip pins nudged to 9 holes | F2: 3 | G2: 107 | H2: =IF(G2="","Not in list",IFERROR(INDEX(Components!$K$2:$K$158,MATCH(G2,Components!$A$2:$A$158,0)),"Not in list")) -> Awaiting delivery
A3: 2 | B3: Board 1 | C3: F1 | D3: Glass fuse 5x20 slow blow | E3: 3.15 A (pump) | F3: 1 | G3: 104 | H3: =IF(G3="","Not in list",IFERROR(INDEX(Components!$K$2:$K$158,MATCH(G3,Components!$A$2:$A$158,0)),"Not in list")) -> Awaiting delivery
A4: 3 | B4: Board 1 | C4: F2, F3 | D4: Glass fuse 5x20 slow blow | E4: 1 A (fans; solenoid + valve) | F4: 2 | G4: 103 | H4: =IF(G4="","Not in list",IFERROR(INDEX(Components!$K$2:$K$158,MATCH(G4,Components!$A$2:$A$158,0)),"Not in list")) -> Awaiting delivery
A5: 4 | B5: Board 1 | C5: C1 | D5: Electrolytic capacitor | E5: 470 uF 25 V, legs bent to 5.08 mm | F5: 1 | G5: 100 | H5: =IF(G5="","Not in list",IFERROR(INDEX(Components!$K$2:$K$158,MATCH(G5,Components!$A$2:$A$158,0)),"Not in list")) -> Awaiting delivery
A6: 5 | B6: Board 1 | C6: M1, M2, M3 | D6: IRF4905 P-channel MOSFET | E6: TO-220; valve open, valve close, pump 2 high-side | F6: 3 | G6: 85 | H6: =IF(G6="","Not in list",IFERROR(INDEX(Components!$K$2:$K$158,MATCH(G6,Components!$A$2:$A$158,0)),"Not in list")) -> Processing
A7: 6 | B7: Board 1 | C7: M4 | D7: IRLB8721 N-channel MOSFET | E7: TO-220; solenoid low-side | F7: 1 | G7: 84 | H7: =IF(G7="","Not in list",IFERROR(INDEX(Components!$K$2:$K$158,MATCH(G7,Components!$A$2:$A$158,0)),"Not in list")) -> Awaiting delivery
A8: 7 | B8: Board 1 | C8: T1, T2, T3 | D8: BC547 NPN transistor | E8: TO-92 gate drivers | F8: 3 | G8: 86 | H8: =IF(G8="","Not in list",IFERROR(INDEX(Components!$K$2:$K$158,MATCH(G8,Components!$A$2:$A$158,0)),"Not in list")) -> Processing
A9: 8 | B9: Board 1 | C9: D1, D2 | D9: 1N5819 Schottky diode | E9: Valve output flyback | F9: 2 | G9: 88 | H9: =IF(G9="","Not in list",IFERROR(INDEX(Components!$K$2:$K$158,MATCH(G9,Components!$A$2:$A$158,0)),"Not in list")) -> Awaiting delivery
A10: 9 | B10: Board 1 | C10: R1, R3, R5 | D10: Resistor 47k | E10: Fuse-sense divider top | F10: 3 | G10: 136 | H10: =IF(G10="","Not in list",IFERROR(INDEX(Components!$K$2:$K$158,MATCH(G10,Components!$A$2:$A$158,0)),"Not in list")) -> Ordered
A11: 10 | B11: Board 1 | C11: R2, R4, R6 | D11: Resistor 20k | E11: Fuse-sense divider bottom | F11: 3 | G11: 136 | H11: =IF(G11="","Not in list",IFERROR(INDEX(Components!$K$2:$K$158,MATCH(G11,Components!$A$2:$A$158,0)),"Not in list")) -> Ordered
A12: 11 | B12: Board 1 | C12: R7, R8, R9, R10 | D12: Resistor 10k | E12: Gate pull-ups x3, M4 gate pull-down | F12: 4 | G12: 94 | H12: =IF(G12="","Not in list",IFERROR(INDEX(Components!$K$2:$K$158,MATCH(G12,Components!$A$2:$A$158,0)),"Not in list")) -> Awaiting delivery
A13: 12 | B13: Board 1 | C13: T1b, T2b, T3b | D13: Resistor 1k | E13: Base resistors | F13: 3 | G13: 136 | H13: =IF(G13="","Not in list",IFERROR(INDEX(Components!$K$2:$K$158,MATCH(G13,Components!$A$2:$A$158,0)),"Not in list")) -> Ordered
... A55: 54 | B55: Off-board | C55: Insulation | D55: Heat shrink 3:1 dual-wall | E55: GX solder cups, pigtails, coil diode | F55: 1 | G55: 129 | H55: =IF(G55="","Not in list",IFERROR(INDEX(Components!$K$2:$K$158,MATCH(G55,Components!$A$2:$A$158,0)),"Not in list")) -> Awaiting delivery
A56: 55 | B56: Off-board | C56: Box entry | D56: Grommet or cable gland + zip ties | E56: Strain relief for hardwired C3 and C4 into the box | F56: 2 | H56: =IF(G56="","Not in list",IFERROR(INDEX(Components!$K$2:$K$158,MATCH(G56,Components!$A$2:$A$158,0)),"Not in list")) -> Not in list
B58: Qty needed counts parts on both boards plus off-board items for rev 4b with display CS, no spares. Blue = input. Status is pulled live from Components column K using the # in column G.
B59: Bought but not used in rev 4b: relay modules (12 V, 24 V), SHT30 modules, SB560 diodes, 3296W trimmers, ferrite rings, 0.91" OLEDs.
